[2023-12-21 13:32:22 +0800] [146583] [INFO] Starting gunicorn 20.1.0
[2023-12-21 13:32:22 +0800] [146583] [INFO] Listening at: http://0.0.0.0:5000 (146583)
[2023-12-21 13:32:22 +0800] [146583] [INFO] Using worker: sync
[2023-12-21 13:32:22 +0800] [146584] [INFO] Booting worker with pid: 146584
[2023-12-21 13:32:22 +0800] [146584] [ERROR] Exception in worker process
Traceback (most recent call last):
  File "/usr/lib/python3/dist-packages/gunicorn/arbiter.py", line 589, in spawn_worker
    worker.init_process()
  File "/usr/lib/python3/dist-packages/gunicorn/workers/base.py", line 134, in init_process
    self.load_wsgi()
  File "/usr/lib/python3/dist-packages/gunicorn/workers/base.py", line 146, in load_wsgi
    self.wsgi = self.app.wsgi()
  File "/usr/lib/python3/dist-packages/gunicorn/app/base.py", line 67, in wsgi
    self.callable = self.load()
  File "/usr/lib/python3/dist-packages/gunicorn/app/wsgiapp.py", line 58, in load
    return self.load_wsgiapp()
  File "/usr/lib/python3/dist-packages/gunicorn/app/wsgiapp.py", line 48, in load_wsgiapp
    return util.import_app(self.app_uri)
  File "/usr/lib/python3/dist-packages/gunicorn/util.py", line 384, in import_app
    mod = importlib.import_module(module)
  File "/usr/lib/python3.10/importlib/__init__.py", line 126, in import_module
    return _bootstrap._gcd_import(name[level:], package, level)
  File "<frozen importlib._bootstrap>", line 1050, in _gcd_import
  File "<frozen importlib._bootstrap>", line 1027, in _find_and_load
  File "<frozen importlib._bootstrap>", line 1006, in _find_and_load_unlocked
  File "<frozen importlib._bootstrap>", line 688, in _load_unlocked
  File "<frozen importlib._bootstrap_external>", line 883, in exec_module
  File "<frozen importlib._bootstrap>", line 241, in _call_with_frames_removed
  File "/Chataaa_System/chataaa/back_end/app.py", line 12, in <module>
    from blue_prints import (
  File "/Chataaa_System/chataaa/back_end/blue_prints/login_system.py", line 11, in <module>
    import flask_login
ModuleNotFoundError: No module named 'flask_login'
[2023-12-21 13:32:22 +0800] [146584] [INFO] Worker exiting (pid: 146584)
[2023-12-21 13:32:22 +0800] [146585] [INFO] Booting worker with pid: 146585
[2023-12-21 13:32:22 +0800] [146585] [ERROR] Exception in worker process
Traceback (most recent call last):
  File "/usr/lib/python3/dist-packages/gunicorn/arbiter.py", line 589, in spawn_worker
    worker.init_process()
  File "/usr/lib/python3/dist-packages/gunicorn/workers/base.py", line 134, in init_process
    self.load_wsgi()
  File "/usr/lib/python3/dist-packages/gunicorn/workers/base.py", line 146, in load_wsgi
    self.wsgi = self.app.wsgi()
  File "/usr/lib/python3/dist-packages/gunicorn/app/base.py", line 67, in wsgi
    self.callable = self.load()
  File "/usr/lib/python3/dist-packages/gunicorn/app/wsgiapp.py", line 58, in load
    return self.load_wsgiapp()
  File "/usr/lib/python3/dist-packages/gunicorn/app/wsgiapp.py", line 48, in load_wsgiapp
    return util.import_app(self.app_uri)
  File "/usr/lib/python3/dist-packages/gunicorn/util.py", line 384, in import_app
    mod = importlib.import_module(module)
  File "/usr/lib/python3.10/importlib/__init__.py", line 126, in import_module
    return _bootstrap._gcd_import(name[level:], package, level)
  File "<frozen importlib._bootstrap>", line 1050, in _gcd_import
  File "<frozen importlib._bootstrap>", line 1027, in _find_and_load
  File "<frozen importlib._bootstrap>", line 1006, in _find_and_load_unlocked
  File "<frozen importlib._bootstrap>", line 688, in _load_unlocked
  File "<frozen importlib._bootstrap_external>", line 883, in exec_module
  File "<frozen importlib._bootstrap>", line 241, in _call_with_frames_removed
  File "/Chataaa_System/chataaa/back_end/app.py", line 12, in <module>
    from blue_prints import (
  File "/Chataaa_System/chataaa/back_end/blue_prints/login_system.py", line 11, in <module>
    import flask_login
ModuleNotFoundError: No module named 'flask_login'
[2023-12-21 13:32:22 +0800] [146585] [INFO] Worker exiting (pid: 146585)
Traceback (most recent call last):
  File "/usr/lib/python3/dist-packages/gunicorn/arbiter.py", line 202, in run
    self.manage_workers()
  File "/usr/lib/python3/dist-packages/gunicorn/arbiter.py", line 551, in manage_workers
    self.spawn_workers()
  File "/usr/lib/python3/dist-packages/gunicorn/arbiter.py", line 623, in spawn_workers
    time.sleep(0.1 * random.random())
  File "/usr/lib/python3/dist-packages/gunicorn/arbiter.py", line 242, in handle_chld
    self.reap_workers()
  File "/usr/lib/python3/dist-packages/gunicorn/arbiter.py", line 525, in reap_workers
    raise HaltServer(reason, self.WORKER_BOOT_ERROR)
gunicorn.errors.HaltServer: <HaltServer 'Worker failed to boot.' 3>

During handling of the above exception, another exception occurred:

Traceback (most recent call last):
  File "/usr/bin/gunicorn", line 33, in <module>
    sys.exit(load_entry_point('gunicorn==20.1.0', 'console_scripts', 'gunicorn')())
  File "/usr/lib/python3/dist-packages/gunicorn/app/wsgiapp.py", line 67, in run
    WSGIApplication("%(prog)s [OPTIONS] [APP_MODULE]").run()
  File "/usr/lib/python3/dist-packages/gunicorn/app/base.py", line 231, in run
    super().run()
  File "/usr/lib/python3/dist-packages/gunicorn/app/base.py", line 72, in run
    Arbiter(self).run()
  File "/usr/lib/python3/dist-packages/gunicorn/arbiter.py", line 229, in run
    self.halt(reason=inst.reason, exit_status=inst.exit_status)
  File "/usr/lib/python3/dist-packages/gunicorn/arbiter.py", line 342, in halt
    self.stop()
  File "/usr/lib/python3/dist-packages/gunicorn/arbiter.py", line 393, in stop
    time.sleep(0.1)
  File "/usr/lib/python3/dist-packages/gunicorn/arbiter.py", line 242, in handle_chld
    self.reap_workers()
  File "/usr/lib/python3/dist-packages/gunicorn/arbiter.py", line 525, in reap_workers
    raise HaltServer(reason, self.WORKER_BOOT_ERROR)
gunicorn.errors.HaltServer: <HaltServer 'Worker failed to boot.' 3>
